Workbook

Sheet 2022a_250206_1736
A1: Run | B1: Preset | C1: Body | D1: SuspF | E1: Tire | F1: TirDyn | G1: Drv | H1: Trail | I1: Mane | J1: Solv | K1: # Steps | L1: Time | M1: xFinal | N1: yFinal | O1: Figure | P1: Pass | R1: 06-Feb-2025 20:10:21
A2: 1 | B2: 0 | C2: HambaLG | D2: dwb | E2: MFEval | F2: steady | G2: f1Dr1D | H2: None | I2: WOT Braking | J2: ode23t | K2: 405 | L2: 7.1740468 | M2: 233.85666 | N2: 0.01469867 | O2: =HYPERLINK(".\sm_car_250206_1736\sm_car_250206_1736_001_Ca000TrN_MaWOT_ode23t.png","figure") -> figure | P2: Pass | R2: MATHWORKS-OL1OH
A3: 2 | B3: 0 | C3: HambaLG | D3: dwb | E3: MFEval | F3: steady | G3: f1Dr1D | H3: None | I3: Low Speed Steer | J3: ode23t | K3: 530 | L3: 7.5204423 | M3: 71.998676 | N3: -0.55228019 | O3: =HYPERLINK(".\sm_car_250206_1736\sm_car_250206_1736_002_Ca000TrN_MaLSS_ode23t.png","figure") -> figure | P3: Pass | R3: 9.12.0.2529717 (R2022a) Update 8
A4: 3 | B4: 1 | C4: HambaLG | D4: dwb | E4: MFEval | F4: steady | G4: f1D3Dr1D | H4: None | I4: WOT Braking | J4: ode23t | K4: 408 | L4: 7.8751305 | M4: 232.87017 | N4: -0.0016387418 | O4: =HYPERLINK(".\sm_car_250206_1736\sm_car_250206_1736_003_Ca001TrN_MaWOT_ode23t.png","figure") -> figure | P4: Pass | R4: MF-Swift Version: 2306
A5: 4 | B5: 1 | C5: HambaLG | D5: dwb | E5: MFEval | F5: steady | G5: f1D3Dr1D | H5: None | I5: Low Speed Steer | J5: ode23t | K5: 522 | L5: 8.0684342 | M5: 71.688581 | N5: -0.54782941 | O5: =HYPERLINK(".\sm_car_250206_1736\sm_car_250206_1736_004_Ca001TrN_MaLSS_ode23t.png","figure") -> figure | P5: Pass | R5: v3p8 R22asrc driverPTBSVDBS
A6: 5 | B6: 2 | C6: HambaLG | D6: dwb | E6: MFEval | F6: steady | G6: fCVpCVr1D | H6: None | I6: WOT Braking | J6: ode23t | K6: 428 | L6: 11.565881 | M6: 232.97358 | N6: 0.085568925 | O6: =HYPERLINK(".\sm_car_250206_1736\sm_car_250206_1736_005_Ca002TrN_MaWOT_ode23t.png","figure") -> figure | P6: Pass
A7: 6 | B7: 2 | C7: HambaLG | D7: dwb | E7: MFEval | F7: steady | G7: fCVpCVr1D | H7: None | I7: Low Speed Steer | J7: ode23t | K7: 528 | L7: 11.236034 | M7: 71.712082 | N7: -0.54151327 | O7: =HYPERLINK(".\sm_car_250206_1736\sm_car_250206_1736_006_Ca002TrN_MaLSS_ode23t.png","figure") -> figure | P7: Pass
A8: 7 | B8: 3 | C8: HambaLG | D8: dwb | E8: MFEval | F8: steady | G8: fCVpCVflexr1D | H8: None | I8: WOT Braking | J8: ode23t | K8: 489 | L8: 13.163961 | M8: 232.34106 | N8: -0.048462793 | O8: =HYPERLINK(".\sm_car_250206_1736\sm_car_250206_1736_007_Ca003TrN_MaWOT_ode23t.png","figure") -> figure | P8: Pass
A9: 8 | B9: 3 | C9: HambaLG | D9: dwb | E9: MFEval | F9: steady | G9: fCVpCVflexr1D | H9: None | I9: Low Speed Steer | J9: ode23t | K9: 548 | L9: 10.8038 | M9: 71.57939 | N9: -0.54118188 | O9: =HYPERLINK(".\sm_car_250206_1736\sm_car_250206_1736_008_Ca003TrN_MaLSS_ode23t.png","figure") -> figure | P9: Pass
A10: 9 | B10: 4 | C10: HambaLG | D10: dwb | E10: MFEval | F10: lintra | G10: f1Dr1D | H10: None | I10: WOT Braking | J10: ode23t | K10: 1115 | L10: 12.863715 | M10: 233.57455 | N10: 0.0064420198 | O10: =HYPERLINK(".\sm_car_250206_1736\sm_car_250206_1736_009_Ca004TrN_MaWOT_ode23t.png","figure") -> figure | P10: Pass
A11: 10 | B11: 4 | C11: HambaLG | D11: dwb | E11: MFEval | F11: lintra | G11: f1Dr1D | H11: None | I11: Low Speed Steer | J11: ode23t | K11: 1235 | L11: 13.246284 | M11: 71.991679 | N11: -0.55302258 | O11: =HYPERLINK(".\sm_car_250206_1736\sm_car_250206_1736_010_Ca004TrN_MaLSS_ode23t.png","figure") -> figure | P11: Pass
A12: 11 | B12: 5 | C12: HambaLG | D12: dwb | E12: MFEval | F12: lintra | G12: f1D3Dr1D | H12: None | I12: WOT Braking | J12: ode23t | K12: 1124 | L12: 14.029448 | M12: 232.8755 | N12: 0.0002839514 | O12: =HYPERLINK(".\sm_car_250206_1736\sm_car_250206_1736_011_Ca005TrN_MaWOT_ode23t.png","figure") -> figure | P12: Pass
A13: 12 | B13: 5 | C13: HambaLG | D13: dwb | E13: MFEval | F13: lintra | G13: f1D3Dr1D | H13: None | I13: Low Speed Steer | J13: ode23t | K13: 1228 | L13: 15.330192 | M13: 71.695992 | N13: -0.54397582 | O13: =HYPERLINK(".\sm_car_250206_1736\sm_car_250206_1736_012_Ca005TrN_MaLSS_ode23t.png","figure") -> figure | P13: Pass
A14: 13 | B14: 6 | C14: HambaLG | D14: dwb | E14: MFEval | F14: lintra | G14: fCVpCVr1D | H14: None | I14: WOT Braking | J14: ode23t | K14: 1265 | L14: 18.071551 | M14: 232.86941 | N14: 0.06881619 | O14: =HYPERLINK(".\sm_car_250206_1736\sm_car_250206_1736_013_Ca006TrN_MaWOT_ode23t.png","figure") -> figure | P14: Pass
A15: 14 | B15: 6 | C15: HambaLG | D15: dwb | E15: MFEval | F15: lintra | G15: fCVpCVr1D | H15: None | I15: Low Speed Steer | J15: ode23t | K15: 1275 | L15: 16.764358 | M15: 71.688618 | N15: -0.54460681 | O15: =HYPERLINK(".\sm_car_250206_1736\sm_car_250206_1736_014_Ca006TrN_MaLSS_ode23t.png","figure") -> figure | P15: Pass
A16: 15 | B16: 7 | C16: HambaLG | D16: dwb | E16: MFEval | F16: lintra | G16: fCVpCVflexr1D | H16: None | I16: WOT Braking | J16: ode23t | K16: 1226 | L16: 18.025031 | M16: 232.37116 | N16: 0.057937016 | O16: =HYPERLINK(".\sm_car_250206_1736\sm_car_250206_1736_015_Ca007TrN_MaWOT_ode23t.png","figure") -> figure | P16: Pass
A17: 16 | B17: 7 | C17: HambaLG | D17: dwb | E17: MFEval | F17: lintra | G17: fCVpCVflexr1D | H17: None | I17: Low Speed Steer | J17: ode23t | K17: 1273 | L17: 16.064877 | M17: 71.56671 | N17: -0.54087591 | O17: =HYPERLINK(".\sm_car_250206_1736\sm_car_250206_1736_016_Ca007TrN_MaLSS_ode23t.png","figure") -> figure | P17: Pass
A18: 17 | B18: 16 | C18: HambaLG | D18: dwa | E18: MFEval | F18: steady | G18: f1Dr1D | H18: None | I18: WOT Braking | J18: ode23t | K18: 408 | L18: 6.0051068 | M18: 234.50888 | N18: -0.070979457 | O18: =HYPERLINK(".\sm_car_250206_1736\sm_car_250206_1736_017_Ca016TrN_MaWOT_ode23t.png","figure") -> figure | P18: Pass
A19: 18 | B19: 16 | C19: HambaLG | D19: dwa | E19: MFEval | F19: steady | G19: f1Dr1D | H19: None | I19: Low Speed Steer | J19: ode23t | K19: 488 | L19: 5.8274708 | M19: 72.265649 | N19: -0.021675994 | O19: =HYPERLINK(".\sm_car_250206_1736\sm_car_250206_1736_018_Ca016TrN_MaLSS_ode23t.png","figure") -> figure | P19: Pass
A20: 19 | B20: 32 | C20: HambaLG | D20: S2LAF | E20: MFEval | F20: steady | G20: f1Dr1D | H20: None | I20: WOT Braking | J20: ode23t | K20: 405 | L20: 8.2639658 | M20: 233.64089 | N20: 0.021192627 | O20: =HYPERLINK(".\sm_car_250206_1736\sm_car_250206_1736_019_Ca032TrN_MaWOT_ode23t.png","figure") -> figure | P20: Pass
A21: 20 | B21: 32 | C21: HambaLG | D21: S2LAF | E21: MFEval | F21: steady | G21: f1Dr1D | H21: None | I21: Low Speed Steer | J21: ode23t | K21: 519 | L21: 8.3274762 | M21: 71.988725 | N21: -0.53279597 | O21: =HYPERLINK(".\sm_car_250206_1736\sm_car_250206_1736_020_Ca032TrN_MaLSS_ode23t.png","figure") -> figure | P21: Pass
A22: 21 | B22: 48 | C22: HambaLG | D22: S2LAR | E22: MFEval | F22: steady | G22: f1Dr1D | H22: None | I22: WOT Braking | J22: ode23t | K22: 392 | L22: 7.3176523 | M22: 233.76185 | N22: -0.0043853866 | O22: =HYPERLINK(".\sm_car_250206_1736\sm_car_250206_1736_021_Ca048TrN_MaWOT_ode23t.png","figure") -> figure | P22: Pass
A23: 22 | B23: 48 | C23: HambaLG | D23: S2LAR | E23: MFEval | F23: steady | G23: f1Dr1D | H23: None | I23: Low Speed Steer | J23: ode23t | K23: 520 | L23: 9.2079311 | M23: 71.987547 | N23: -0.53897106 | O23: =HYPERLINK(".\sm_car_250206_1736\sm_car_250206_1736_022_Ca048TrN_MaLSS_ode23t.png","figure") -> figure | P23: Pass
A24: 23 | B24: 64 | C24: HambaLG | D24: 5S2LAF | E24: MFEval | F24: steady | G24: f1Dr1D | H24: None | I24: WOT Braking | J24: ode23t | K24: 398 | L24: 8.4117453 | M24: 233.73834 | N24: 0.021688879 | O24: =HYPERLINK(".\sm_car_250206_1736\sm_car_250206_1736_023_Ca064TrN_MaWOT_ode23t.png","figure") -> figure | P24: Pass
A25: 24 | B25: 64 | C25: HambaLG | D25: 5S2LAF | E25: MFEval | F25: steady | G25: f1Dr1D | H25: None | I25: Low Speed Steer | J25: ode23t | K25: 527 | L25: 9.02925 | M25: 72.005755 | N25: -0.52789155 | O25: =HYPERLINK(".\sm_car_250206_1736\sm_car_250206_1736_024_Ca064TrN_MaLSS_ode23t.png","figure") -> figure | P25: Pass
A26: 25 | B26: 80 | C26: HambaLG | D26: 5S2LAR | E26: MFEval | F26: steady | G26: f1Dr1D | H26: None | I26: WOT Braking | J26: ode23t | K26: 405 | L26: 9.8118068 | M26: 233.76989 | N26: -0.0057554177 | O26: =HYPERLINK(".\sm_car_250206_1736\sm_car_250206_1736_025_Ca080TrN_MaWOT_ode23t.png","figure") -> figure | P26: Pass
A27: 26 | B27: 80 | C27: HambaLG | D27: 5S2LAR | E27: MFEval | F27: steady | G27: f1Dr1D | H27: None | I27: Low Speed Steer | J27: ode23t | K27: 518 | L27: 8.9876971 | M27: 71.987062 | N27: -0.53765599 | O27: =HYPERLINK(".\sm_car_250206_1736\sm_car_250206_1736_026_Ca080TrN_MaLSS_ode23t.png","figure") -> figure | P27: Pass
A28: 27 | B28: 96 | C28: HambaLG | D28: 5CS2LAF | E28: MFEval | F28: steady | G28: f1Dr1D | H28: None | I28: WOT Braking | J28: ode23t | K28: 415 | L28: 6.750561 | M28: 235.611 | N28: 0.030590079 | O28: =HYPERLINK(".\sm_car_250206_1736\sm_car_250206_1736_027_Ca096TrN_MaWOT_ode23t.png","figure") -> figure | P28: Pass
A29: 28 | B29: 96 | C29: HambaLG | D29: 5CS2LAF | E29: MFEval | F29: steady | G29: f1Dr1D | H29: None | I29: Low Speed Steer | J29: ode23t | K29: 519 | L29: 6.6101515 | M29: 72.511817 | N29: -0.53964081 | O29: =HYPERLINK(".\sm_car_250206_1736\sm_car_250206_1736_028_Ca096TrN_MaLSS_ode23t.png","figure") -> figure | P29: Pass
A30: 29 | B30: 112 | C30: HambaLG | D30: 15DOF | E30: MFEval | F30: steady | G30: f1Dr1D | H30: None | I30: WOT Braking | J30: ode23t | K30: 371 | L30: 2.4924347 | M30: 242.67152 | N30: 0.23455913 | O30: =HYPERLINK(".\sm_car_250206_1736\sm_car_250206_1736_029_Ca112TrN_MaWOT_ode23t.png","figure") -> figure | P30: Pass
A31: 30 | B31: 112 | C31: HambaLG | D31: 15DOF | E31: MFEval | F31: steady | G31: f1Dr1D | H31: None | I31: Low Speed Steer | J31: ode23t | K31: 480 | L31: 2.7779492 | M31: 74.659634 | N31: -0.33798931 | O31: =HYPERLINK(".\sm_car_250206_1736\sm_car_250206_1736_030_Ca112TrN_MaLSS_ode23t.png","figure") -> figure | P31: Pass
A32: 31 | B32: 113 | C32: HambaLG | D32: 15DOF | E32: MFEval | F32: steady | G32: f1D3Dr1D | H32: None | I32: WOT Braking | J32: ode23t | K32: 366 | L32: 2.9230039 | M32: 241.4988 | N32: 0.22933556 | O32: =HYPERLINK(".\sm_car_250206_1736\sm_car_250206_1736_031_Ca113TrN_MaWOT_ode23t.png","figure") -> figure | P32: Pass
A33: 32 | B33: 113 | C33: HambaLG | D33: 15DOF | E33: MFEval | F33: steady | G33: f1D3Dr1D | H33: None | I33: Low Speed Steer | J33: ode23t | K33: 487 | L33: 3.2996583 | M33: 74.346228 | N33: -0.33396938 | O33: =HYPERLINK(".\sm_car_250206_1736\sm_car_250206_1736_032_Ca113TrN_MaLSS_ode23t.png","figure") -> figure | P33: Pass
A34: 33 | B34: 114 | C34: HambaLG | D34: 15DOF | E34: MFEval | F34: steady | G34: fCVpCVr1D | H34: None | I34: WOT Braking | J34: ode23t | K34: 382 | L34: 3.1467154 | M34: 241.61378 | N34: 0.23021245 | O34: =HYPERLINK(".\sm_car_250206_1736\sm_car_250206_1736_033_Ca114TrN_MaWOT_ode23t.png","figure") -> figure | P34: Pass
A35: 34 | B35: 114 | C35: HambaLG | D35: 15DOF | E35: MFEval | F35: steady | G35: fCVpCVr1D | H35: None | I35: Low Speed Steer | J35: ode23t | K35: 482 | L35: 3.2255832 | M35: 74.351409 | N35: -0.3342006 | O35: =HYPERLINK(".\sm_car_250206_1736\sm_car_250206_1736_034_Ca114TrN_MaLSS_ode23t.png","figure") -> figure | P35: Pass
A36: 35 | B36: 115 | C36: HambaLG | D36: 15DOF | E36: MFEval | F36: steady | G36: fCVpCVflexr1D | H36: None | I36: WOT Braking | J36: ode23t | K36: 394 | L36: 3.1625977 | M36: 241.17294 | N36: 0.22843005 | O36: =HYPERLINK(".\sm_car_250206_1736\sm_car_250206_1736_035_Ca115TrN_MaWOT_ode23t.png","figure") -> figure | P36: Pass
A37: 36 | B37: 115 | C37: HambaLG | D37: 15DOF | E37: MFEval | F37: steady | G37: fCVpCVflexr1D | H37: None | I37: Low Speed Steer | J37: ode23t | K37: 505 | L37: 3.4018562 | M37: 74.209226 | N37: -0.33168045 | O37: =HYPERLINK(".\sm_car_250206_1736\sm_car_250206_1736_036_Ca115TrN_MaLSS_ode23t.png","figure") -> figure | P37: Pass
A38: 37 | B38: 116 | C38: HambaLG | D38: 15DOF | E38: MFEval | F38: lintra | G38: f1Dr1D | H38: None | I38: WOT Braking | J38: ode23t | K38: 943 | L38: 4.5672407 | M38: 242.63119 | N38: 0.23279194 | O38: =HYPERLINK(".\sm_car_250206_1736\sm_car_250206_1736_037_Ca116TrN_MaWOT_ode23t.png","figure") -> figure | P38: Pass
A39: 38 | B39: 116 | C39: HambaLG | D39: 15DOF | E39: MFEval | F39: lintra | G39: f1Dr1D | H39: None | I39: Low Speed Steer | J39: ode23t | K39: 1060 | L39: 5.0453644 | M39: 74.660234 | N39: -0.34043153 | O39: =HYPERLINK(".\sm_car_250206_1736\sm_car_250206_1736_038_Ca116TrN_MaLSS_ode23t.png","figure") -> figure | P39: Pass
A40: 39 | B40: 117 | C40: HambaLG | D40: 15DOF | E40: MFEval | F40: lintra | G40: f1D3Dr1D | H40: None | I40: WOT Braking | J40: ode23t | K40: 951 | L40: 5.1886307 | M40: 241.56098 | N40: 0.2297138 | O40: =HYPERLINK(".\sm_car_250206_1736\sm_car_250206_1736_039_Ca117TrN_MaWOT_ode23t.png","figure") -> figure | P40: Pass
...

Sheet 2022a_250407_2318
A1: Run | B1: Preset | C1: Body | D1: SuspF | E1: Tire | F1: TirDyn | G1: Drv | H1: Trail | I1: Mane | J1: Solv | K1: # Steps | L1: Time | M1: xFinal | N1: yFinal | O1: Figure | P1: Pass | R1: 08-Apr-2025 01:47:05
A2: 1 | B2: 0 | C2: HambaLG | D2: dwb | E2: MFEval | F2: steady | G2: f1Dr1D | H2: None | I2: WOT Braking | J2: ode23t | K2: 419 | L2: 6.5229168 | M2: 231.16978 | N2: -0.0042167209 | O2: =HYPERLINK(".\sm_car_250407_2318\sm_car_250407_2318_001_Ca000TrN_MaWOT_ode23t.png","figure") -> figure | P2: Pass | R2: MATHWORKS-OL1OH | T2: =K2-'2022a_250206_1736'!K2 -> 14 | U2: =T2/'2022a_250206_1736'!K2 -> 0.034567901 | V2: =L2-'2022a_250206_1736'!L2 -> -0.65113 | W2: =V2/'2022a_250206_1736'!L2 -> -0.090761884
A3: 2 | B3: 0 | C3: HambaLG | D3: dwb | E3: MFEval | F3: steady | G3: f1Dr1D | H3: None | I3: Low Speed Steer | J3: ode23t | K3: 535 | L3: 7.5437127 | M3: 71.237682 | N3: -0.53746461 | O3: =HYPERLINK(".\sm_car_250407_2318\sm_car_250407_2318_002_Ca000TrN_MaLSS_ode23t.png","figure") -> figure | P3: Pass | R3: 9.12.0.2529717 (R2022a) Update 8 | T3: =K3-'2022a_250206_1736'!K3 -> 5 | U3: =T3/'2022a_250206_1736'!K3 -> 0.0094339623 | V3: =L3-'2022a_250206_1736'!L3 -> 0.0232704 | W3: =V3/'2022a_250206_1736'!L3 -> 0.0030942861
A4: 3 | B4: 1 | C4: HambaLG | D4: dwb | E4: MFEval | F4: steady | G4: f1D3Dr1D | H4: None | I4: WOT Braking | J4: ode23t | K4: 422 | L4: 7.2873893 | M4: 230.37135 | N4: -0.010327302 | O4: =HYPERLINK(".\sm_car_250407_2318\sm_car_250407_2318_003_Ca001TrN_MaWOT_ode23t.png","figure") -> figure | P4: Pass | R4: MF-Swift Version: 2306 | T4: =K4-'2022a_250206_1736'!K4 -> 14 | U4: =T4/'2022a_250206_1736'!K4 -> 0.034313725 | V4: =L4-'2022a_250206_1736'!L4 -> -0.5877412 | W4: =V4/'2022a_250206_1736'!L4 -> -0.074632566
A5: 4 | B5: 1 | C5: HambaLG | D5: dwb | E5: MFEval | F5: steady | G5: f1D3Dr1D | H5: None | I5: Low Speed Steer | J5: ode23t | K5: 519 | L5: 7.9593995 | M5: 70.957359 | N5: -0.53535025 | O5: =HYPERLINK(".\sm_car_250407_2318\sm_car_250407_2318_004_Ca001TrN_MaLSS_ode23t.png","figure") -> figure | P5: Pass | R5: R22asrc v4p0 knc bushings pushrod | T5: =K5-'2022a_250206_1736'!K5 -> -3 | U5: =T5/'2022a_250206_1736'!K5 -> -0.0057471264 | V5: =L5-'2022a_250206_1736'!L5 -> -0.1090347 | W5: =V5/'2022a_250206_1736'!L5 -> -0.013513737
A6: 5 | B6: 2 | C6: HambaLG | D6: dwb | E6: MFEval | F6: steady | G6: fCVpCVr1D | H6: None | I6: WOT Braking | J6: ode23t | K6: 438 | L6: 11.166279 | M6: 230.38665 | N6: 0.052552456 | O6: =HYPERLINK(".\sm_car_250407_2318\sm_car_250407_2318_005_Ca002TrN_MaWOT_ode23t.png","figure") -> figure | P6: Pass | T6: =K6-'2022a_250206_1736'!K6 -> 10 | U6: =T6/'2022a_250206_1736'!K6 -> 0.023364486 | V6: =L6-'2022a_250206_1736'!L6 -> -0.3996013 | W6: =V6/'2022a_250206_1736'!L6 -> -0.03455001
A7: 6 | B7: 2 | C7: HambaLG | D7: dwb | E7: MFEval | F7: steady | G7: fCVpCVr1D | H7: None | I7: Low Speed Steer | J7: ode23t | K7: 531 | L7: 11.782131 | M7: 70.954822 | N7: -0.5320192 | O7: =HYPERLINK(".\sm_car_250407_2318\sm_car_250407_2318_006_Ca002TrN_MaLSS_ode23t.png","figure") -> figure | P7: Pass | T7: =K7-'2022a_250206_1736'!K7 -> 3 | U7: =T7/'2022a_250206_1736'!K7 -> 0.0056818182 | V7: =L7-'2022a_250206_1736'!L7 -> 0.5460977 | W7: =V7/'2022a_250206_1736'!L7 -> 0.048602355
A8: 7 | B8: 3 | C8: HambaLG | D8: dwb | E8: MFEval | F8: steady | G8: fCVpCVflexr1D | H8: None | I8: WOT Braking | J8: ode23t | K8: 462 | L8: 10.993606 | M8: 229.97511 | N8: 0.051365342 | O8: =HYPERLINK(".\sm_car_250407_2318\sm_car_250407_2318_007_Ca003TrN_MaWOT_ode23t.png","figure") -> figure | P8: Pass | T8: =K8-'2022a_250206_1736'!K8 -> -27 | U8: =T8/'2022a_250206_1736'!K8 -> -0.055214724 | V8: =L8-'2022a_250206_1736'!L8 -> -2.1703553 | W8: =V8/'2022a_250206_1736'!L8 -> -0.16487099
A9: 8 | B9: 3 | C9: HambaLG | D9: dwb | E9: MFEval | F9: steady | G9: fCVpCVflexr1D | H9: None | I9: Low Speed Steer | J9: ode23t | K9: 583 | L9: 12.161258 | M9: 70.83711 | N9: -0.52818838 | O9: =HYPERLINK(".\sm_car_250407_2318\sm_car_250407_2318_008_Ca003TrN_MaLSS_ode23t.png","figure") -> figure | P9: Pass | T9: =K9-'2022a_250206_1736'!K9 -> 35 | U9: =T9/'2022a_250206_1736'!K9 -> 0.063868613 | V9: =L9-'2022a_250206_1736'!L9 -> 1.3574582 | W9: =V9/'2022a_250206_1736'!L9 -> 0.12564637
A10: 9 | B10: 4 | C10: HambaLG | D10: dwb | E10: MFEval | F10: lintra | G10: f1Dr1D | H10: None | I10: WOT Braking | J10: ode23t | K10: 1083 | L10: 10.782206 | M10: 231.36499 | N10: -0.0056787031 | O10: =HYPERLINK(".\sm_car_250407_2318\sm_car_250407_2318_009_Ca004TrN_MaWOT_ode23t.png","figure") -> figure | P10: Pass | T10: =K10-'2022a_250206_1736'!K10 -> -32 | U10: =T10/'2022a_250206_1736'!K10 -> -0.028699552 | V10: =L10-'2022a_250206_1736'!L10 -> -2.081509 | W10: =V10/'2022a_250206_1736'!L10 -> -0.16181243
A11: 10 | B11: 4 | C11: HambaLG | D11: dwb | E11: MFEval | F11: lintra | G11: f1Dr1D | H11: None | I11: Low Speed Steer | J11: ode23t | K11: 1204 | L11: 12.687814 | M11: 71.25104 | N11: -0.5401557 | O11: =HYPERLINK(".\sm_car_250407_2318\sm_car_250407_2318_010_Ca004TrN_MaLSS_ode23t.png","figure") -> figure | P11: Pass | T11: =K11-'2022a_250206_1736'!K11 -> -31 | U11: =T11/'2022a_250206_1736'!K11 -> -0.025101215 | V11: =L11-'2022a_250206_1736'!L11 -> -0.5584697 | W11: =V11/'2022a_250206_1736'!L11 -> -0.042160481
A12: 11 | B12: 5 | C12: HambaLG | D12: dwb | E12: MFEval | F12: lintra | G12: f1D3Dr1D | H12: None | I12: WOT Braking | J12: ode23t | K12: 1114 | L12: 12.376304 | M12: 230.37145 | N12: -0.01174034 | O12: =HYPERLINK(".\sm_car_250407_2318\sm_car_250407_2318_011_Ca005TrN_MaWOT_ode23t.png","figure") -> figure | P12: Pass | T12: =K12-'2022a_250206_1736'!K12 -> -10 | U12: =T12/'2022a_250206_1736'!K12 -> -0.0088967972 | V12: =L12-'2022a_250206_1736'!L12 -> -1.6531435 | W12: =V12/'2022a_250206_1736'!L12 -> -0.11783383
A13: 12 | B13: 5 | C13: HambaLG | D13: dwb | E13: MFEval | F13: lintra | G13: f1D3Dr1D | H13: None | I13: Low Speed Steer | J13: ode23t | K13: 1231 | L13: 13.822515 | M13: 70.973896 | N13: -0.53888735 | O13: =HYPERLINK(".\sm_car_250407_2318\sm_car_250407_2318_012_Ca005TrN_MaLSS_ode23t.png","figure") -> figure | P13: Pass | T13: =K13-'2022a_250206_1736'!K13 -> 3 | U13: =T13/'2022a_250206_1736'!K13 -> 0.0024429967 | V13: =L13-'2022a_250206_1736'!L13 -> -1.5076765 | W13: =V13/'2022a_250206_1736'!L13 -> -0.098346878
A14: 13 | B14: 6 | C14: HambaLG | D14: dwb | E14: MFEval | F14: lintra | G14: fCVpCVr1D | H14: None | I14: WOT Braking | J14: ode23t | K14: 1205 | L14: 14.859066 | M14: 230.41604 | N14: 0.051014451 | O14: =HYPERLINK(".\sm_car_250407_2318\sm_car_250407_2318_013_Ca006TrN_MaWOT_ode23t.png","figure") -> figure | P14: Pass | T14: =K14-'2022a_250206_1736'!K14 -> -60 | U14: =T14/'2022a_250206_1736'!K14 -> -0.04743083 | V14: =L14-'2022a_250206_1736'!L14 -> -3.2124847 | W14: =V14/'2022a_250206_1736'!L14 -> -0.17776475
A15: 14 | B15: 6 | C15: HambaLG | D15: dwb | E15: MFEval | F15: lintra | G15: fCVpCVr1D | H15: None | I15: Low Speed Steer | J15: ode23t | K15: 1302 | L15: 15.321896 | M15: 70.962447 | N15: -0.53379822 | O15: =HYPERLINK(".\sm_car_250407_2318\sm_car_250407_2318_014_Ca006TrN_MaLSS_ode23t.png","figure") -> figure | P15: Pass | T15: =K15-'2022a_250206_1736'!K15 -> 27 | U15: =T15/'2022a_250206_1736'!K15 -> 0.021176471 | V15: =L15-'2022a_250206_1736'!L15 -> -1.4424621 | W15: =V15/'2022a_250206_1736'!L15 -> -0.086043383
A16: 15 | B16: 7 | C16: HambaLG | D16: dwb | E16: MFEval | F16: lintra | G16: fCVpCVflexr1D | H16: None | I16: WOT Braking | J16: ode23t | K16: 1187 | L16: 17.170935 | M16: 229.92141 | N16: 0.055510013 | O16: =HYPERLINK(".\sm_car_250407_2318\sm_car_250407_2318_015_Ca007TrN_MaWOT_ode23t.png","figure") -> figure | P16: Pass | T16: =K16-'2022a_250206_1736'!K16 -> -39 | U16: =T16/'2022a_250206_1736'!K16 -> -0.031810767 | V16: =L16-'2022a_250206_1736'!L16 -> -0.854096 | W16: =V16/'2022a_250206_1736'!L16 -> -0.047383886
A17: 16 | B17: 7 | C17: HambaLG | D17: dwb | E17: MFEval | F17: lintra | G17: fCVpCVflexr1D | H17: None | I17: Low Speed Steer | J17: ode23t | K17: 1264 | L17: 15.799833 | M17: 70.840156 | N17: -0.52950776 | O17: =HYPERLINK(".\sm_car_250407_2318\sm_car_250407_2318_016_Ca007TrN_MaLSS_ode23t.png","figure") -> figure | P17: Pass | T17: =K17-'2022a_250206_1736'!K17 -> -9 | U17: =T17/'2022a_250206_1736'!K17 -> -0.0070699136 | V17: =L17-'2022a_250206_1736'!L17 -> -0.2650442 | W17: =V17/'2022a_250206_1736'!L17 -> -0.016498365
A18: 17 | B18: 16 | C18: HambaLG | D18: dwa | E18: MFEval | F18: steady | G18: f1Dr1D | H18: None | I18: WOT Braking | J18: ode23t | K18: 410 | L18: 5.6012029 | M18: 231.9547 | N18: -0.07180517 | O18: =HYPERLINK(".\sm_car_250407_2318\sm_car_250407_2318_017_Ca016TrN_MaWOT_ode23t.png","figure") -> figure | P18: Pass | T18: =K18-'2022a_250206_1736'!K18 -> 2 | U18: =T18/'2022a_250206_1736'!K18 -> 0.0049019608 | V18: =L18-'2022a_250206_1736'!L18 -> -0.4039039 | W18: =V18/'2022a_250206_1736'!L18 -> -0.067260069
A19: 18 | B19: 16 | C19: HambaLG | D19: dwa | E19: MFEval | F19: steady | G19: f1Dr1D | H19: None | I19: Low Speed Steer | J19: ode23t | K19: 487 | L19: 5.7221568 | M19: 71.519095 | N19: -0.021563941 | O19: =HYPERLINK(".\sm_car_250407_2318\sm_car_250407_2318_018_Ca016TrN_MaLSS_ode23t.png","figure") -> figure | P19: Pass | T19: =K19-'2022a_250206_1736'!K19 -> -1 | U19: =T19/'2022a_250206_1736'!K19 -> -0.0020491803 | V19: =L19-'2022a_250206_1736'!L19 -> -0.105314 | W19: =V19/'2022a_250206_1736'!L19 -> -0.018071991
A20: 19 | B20: 32 | C20: HambaLG | D20: S2LAF | E20: MFEval | F20: steady | G20: f1Dr1D | H20: None | I20: WOT Braking | J20: ode23t | K20: 396 | L20: 6.9070206 | M20: 231.36824 | N20: 0.008704882 | O20: =HYPERLINK(".\sm_car_250407_2318\sm_car_250407_2318_019_Ca032TrN_MaWOT_ode23t.png","figure") -> figure | P20: Pass | T20: =K20-'2022a_250206_1736'!K20 -> -9 | U20: =T20/'2022a_250206_1736'!K20 -> -0.022222222 | V20: =L20-'2022a_250206_1736'!L20 -> -1.3569452 | W20: =V20/'2022a_250206_1736'!L20 -> -0.16420024
A21: 20 | B21: 32 | C21: HambaLG | D21: S2LAF | E21: MFEval | F21: steady | G21: f1Dr1D | H21: None | I21: Low Speed Steer | J21: ode23t | K21: 519 | L21: 8.3026144 | M21: 71.259134 | N21: -0.52291335 | O21: =HYPERLINK(".\sm_car_250407_2318\sm_car_250407_2318_020_Ca032TrN_MaLSS_ode23t.png","figure") -> figure | P21: Pass | T21: =K21-'2022a_250206_1736'!K21 -> 0 | U21: =T21/'2022a_250206_1736'!K21 -> 0 | V21: =L21-'2022a_250206_1736'!L21 -> -0.0248618 | W21: =V21/'2022a_250206_1736'!L21 -> -0.0029855144
A22: 21 | B22: 48 | C22: HambaLG | D22: S2LAR | E22: MFEval | F22: steady | G22: f1Dr1D | H22: None | I22: WOT Braking | J22: ode23t | K22: 408 | L22: 7.3011224 | M22: 231.3545 | N22: -0.017846833 | O22: =HYPERLINK(".\sm_car_250407_2318\sm_car_250407_2318_021_Ca048TrN_MaWOT_ode23t.png","figure") -> figure | P22: Pass | T22: =K22-'2022a_250206_1736'!K22 -> 16 | U22: =T22/'2022a_250206_1736'!K22 -> 0.040816327 | V22: =L22-'2022a_250206_1736'!L22 -> -0.0165299 | W22: =V22/'2022a_250206_1736'!L22 -> -0.0022589075
A23: 22 | B23: 48 | C23: HambaLG | D23: S2LAR | E23: MFEval | F23: steady | G23: f1Dr1D | H23: None | I23: Low Speed Steer | J23: ode23t | K23: 523 | L23: 7.9933804 | M23: 71.243091 | N23: -0.52846715 | O23: =HYPERLINK(".\sm_car_250407_2318\sm_car_250407_2318_022_Ca048TrN_MaLSS_ode23t.png","figure") -> figure | P23: Pass | T23: =K23-'2022a_250206_1736'!K23 -> 3 | U23: =T23/'2022a_250206_1736'!K23 -> 0.0057692308 | V23: =L23-'2022a_250206_1736'!L23 -> -1.2145507 | W23: =V23/'2022a_250206_1736'!L23 -> -0.13190267
A24: 23 | B24: 64 | C24: HambaLG | D24: 5S2LAF | E24: MFEval | F24: steady | G24: f1Dr1D | H24: None | I24: WOT Braking | J24: ode23t | K24: 401 | L24: 8.0803878 | M24: 231.39133 | N24: 0.010575312 | O24: =HYPERLINK(".\sm_car_250407_2318\sm_car_250407_2318_023_Ca064TrN_MaWOT_ode23t.png","figure") -> figure | P24: Pass | T24: =K24-'2022a_250206_1736'!K24 -> 3 | U24: =T24/'2022a_250206_1736'!K24 -> 0.0075376884 | V24: =L24-'2022a_250206_1736'!L24 -> -0.3313575 | W24: =V24/'2022a_250206_1736'!L24 -> -0.039392241
A25: 24 | B25: 64 | C25: HambaLG | D25: 5S2LAF | E25: MFEval | F25: steady | G25: f1Dr1D | H25: None | I25: Low Speed Steer | J25: ode23t | K25: 515 | L25: 7.9374156 | M25: 71.257169 | N25: -0.51773374 | O25: =HYPERLINK(".\sm_car_250407_2318\sm_car_250407_2318_024_Ca064TrN_MaLSS_ode23t.png","figure") -> figure | P25: Pass | T25: =K25-'2022a_250206_1736'!K25 -> -12 | U25: =T25/'2022a_250206_1736'!K25 -> -0.022770398 | V25: =L25-'2022a_250206_1736'!L25 -> -1.0918344 | W25: =V25/'2022a_250206_1736'!L25 -> -0.12092194
A26: 25 | B26: 80 | C26: HambaLG | D26: 5S2LAR | E26: MFEval | F26: steady | G26: f1Dr1D | H26: None | I26: WOT Braking | J26: ode23t | K26: 409 | L26: 8.5497917 | M26: 230.92214 | N26: -0.018904178 | O26: =HYPERLINK(".\sm_car_250407_2318\sm_car_250407_2318_025_Ca080TrN_MaWOT_ode23t.png","figure") -> figure | P26: Pass | T26: =K26-'2022a_250206_1736'!K26 -> 4 | U26: =T26/'2022a_250206_1736'!K26 -> 0.0098765432 | V26: =L26-'2022a_250206_1736'!L26 -> -1.2620151 | W26: =V26/'2022a_250206_1736'!L26 -> -0.12862209
A27: 26 | B27: 80 | C27: HambaLG | D27: 5S2LAR | E27: MFEval | F27: steady | G27: f1Dr1D | H27: None | I27: Low Speed Steer | J27: ode23t | K27: 511 | L27: 8.1875877 | M27: 71.241627 | N27: -0.5275313 | O27: =HYPERLINK(".\sm_car_250407_2318\sm_car_250407_2318_026_Ca080TrN_MaLSS_ode23t.png","figure") -> figure | P27: Pass | T27: =K27-'2022a_250206_1736'!K27 -> -7 | U27: =T27/'2022a_250206_1736'!K27 -> -0.013513514 | V27: =L27-'2022a_250206_1736'!L27 -> -0.8001094 | W27: =V27/'2022a_250206_1736'!L27 -> -0.089022738
A28: 27 | B28: 96 | C28: HambaLG | D28: 5CS2LAF | E28: MFEval | F28: steady | G28: f1Dr1D | H28: None | I28: WOT Braking | J28: ode23t | K28: 408 | L28: 6.1851631 | M28: 233.14095 | N28: 0.022170176 | O28: =HYPERLINK(".\sm_car_250407_2318\sm_car_250407_2318_027_Ca096TrN_MaWOT_ode23t.png","figure") -> figure | P28: Pass | T28: =K28-'2022a_250206_1736'!K28 -> -7 | U28: =T28/'2022a_250206_1736'!K28 -> -0.01686747 | V28: =L28-'2022a_250206_1736'!L28 -> -0.5653979 | W28: =V28/'2022a_250206_1736'!L28 -> -0.083755691
A29: 28 | B29: 96 | C29: HambaLG | D29: 5CS2LAF | E29: MFEval | F29: steady | G29: f1Dr1D | H29: None | I29: Low Speed Steer | J29: ode23t | K29: 508 | L29: 6.7321201 | M29: 71.764371 | N29: -0.52600636 | O29: =HYPERLINK(".\sm_car_250407_2318\sm_car_250407_2318_028_Ca096TrN_MaLSS_ode23t.png","figure") -> figure | P29: Pass | T29: =K29-'2022a_250206_1736'!K29 -> -11 | U29: =T29/'2022a_250206_1736'!K29 -> -0.021194605 | V29: =L29-'2022a_250206_1736'!L29 -> 0.1219686 | W29: =V29/'2022a_250206_1736'!L29 -> 0.01845171
A30: 29 | B30: 112 | C30: HambaLG | D30: 15DOF | E30: MFEval | F30: steady | G30: f1Dr1D | H30: None | I30: WOT Braking | J30: ode23t | K30: 371 | L30: 2.2592868 | M30: 242.67152 | N30: 0.23455913 | O30: =HYPERLINK(".\sm_car_250407_2318\sm_car_250407_2318_029_Ca112TrN_MaWOT_ode23t.png","figure") -> figure | P30: Pass | T30: =K30-'2022a_250206_1736'!K30 -> 0 | U30: =T30/'2022a_250206_1736'!K30 -> 0 | V30: =L30-'2022a_250206_1736'!L30 -> -0.2331479 | W30: =V30/'2022a_250206_1736'!L30 -> -0.09354223
A31: 30 | B31: 112 | C31: HambaLG | D31: 15DOF | E31: MFEval | F31: steady | G31: f1Dr1D | H31: None | I31: Low Speed Steer | J31: ode23t | K31: 480 | L31: 2.4936378 | M31: 74.659634 | N31: -0.33798931 | O31: =HYPERLINK(".\sm_car_250407_2318\sm_car_250407_2318_030_Ca112TrN_MaLSS_ode23t.png","figure") -> figure | P31: Pass | T31: =K31-'2022a_250206_1736'!K31 -> 0 | U31: =T31/'2022a_250206_1736'!K31 -> 0 | V31: =L31-'2022a_250206_1736'!L31 -> -0.2843114 | W31: =V31/'2022a_250206_1736'!L31 -> -0.10234579
A32: 31 | B32: 113 | C32: HambaLG | D32: 15DOF | E32: MFEval | F32: steady | G32: f1D3Dr1D | H32: None | I32: WOT Braking | J32: ode23t | K32: 366 | L32: 2.6932016 | M32: 241.4988 | N32: 0.22933556 | O32: =HYPERLINK(".\sm_car_250407_2318\sm_car_250407_2318_031_Ca113TrN_MaWOT_ode23t.png","figure") -> figure | P32: Pass | T32: =K32-'2022a_250206_1736'!K32 -> 0 | U32: =T32/'2022a_250206_1736'!K32 -> 0 | V32: =L32-'2022a_250206_1736'!L32 -> -0.2298023 | W32: =V32/'2022a_250206_1736'!L32 -> -0.07861854
A33: 32 | B33: 113 | C33: HambaLG | D33: 15DOF | E33: MFEval | F33: steady | G33: f1D3Dr1D | H33: None | I33: Low Speed Steer | J33: ode23t | K33: 487 | L33: 3.1711091 | M33: 74.346228 | N33: -0.33396938 | O33: =HYPERLINK(".\sm_car_250407_2318\sm_car_250407_2318_032_Ca113TrN_MaLSS_ode23t.png","figure") -> figure | P33: Pass | T33: =K33-'2022a_250206_1736'!K33 -> 0 | U33: =T33/'2022a_250206_1736'!K33 -> 0 | V33: =L33-'2022a_250206_1736'!L33 -> -0.1285492 | W33: =V33/'2022a_250206_1736'!L33 -> -0.038958337
A34: 33 | B34: 114 | C34: HambaLG | D34: 15DOF | E34: MFEval | F34: steady | G34: fCVpCVr1D | H34: None | I34: WOT Braking | J34: ode23t | K34: 382 | L34: 2.907095 | M34: 241.61378 | N34: 0.23021245 | O34: =HYPERLINK(".\sm_car_250407_2318\sm_car_250407_2318_033_Ca114TrN_MaWOT_ode23t.png","figure") -> figure | P34: Pass | T34: =K34-'2022a_250206_1736'!K34 -> 0 | U34: =T34/'2022a_250206_1736'!K34 -> 0 | V34: =L34-'2022a_250206_1736'!L34 -> -0.2396204 | W34: =V34/'2022a_250206_1736'!L34 -> -0.076149372
A35: 34 | B35: 114 | C35: HambaLG | D35: 15DOF | E35: MFEval | F35: steady | G35: fCVpCVr1D | H35: None | I35: Low Speed Steer | J35: ode23t | K35: 482 | L35: 3.1309647 | M35: 74.351409 | N35: -0.3342006 | O35: =HYPERLINK(".\sm_car_250407_2318\sm_car_250407_2318_034_Ca114TrN_MaLSS_ode23t.png","figure") -> figure | P35: Pass | T35: =K35-'2022a_250206_1736'!K35 -> 0 | U35: =T35/'2022a_250206_1736'!K35 -> 0 | V35: =L35-'2022a_250206_1736'!L35 -> -0.0946185 | W35: =V35/'2022a_250206_1736'!L35 -> -0.029333765
A36: 35 | B36: 115 | C36: HambaLG | D36: 15DOF | E36: MFEval | F36: steady | G36: fCVpCVflexr1D | H36: None | I36: WOT Braking | J36: ode23t | K36: 394 | L36: 2.9837028 | M36: 241.17294 | N36: 0.22843005 | O36: =HYPERLINK(".\sm_car_250407_2318\sm_car_250407_2318_035_Ca115TrN_MaWOT_ode23t.png","figure") -> figure | P36: Pass | T36: =K36-'2022a_250206_1736'!K36 -> 0 | U36: =T36/'2022a_250206_1736'!K36 -> 0 | V36: =L36-'2022a_250206_1736'!L36 -> -0.1788949 | W36: =V36/'2022a_250206_1736'!L36 -> -0.05656581
A37: 36 | B37: 115 | C37: HambaLG | D37: 15DOF | E37: MFEval | F37: steady | G37: fCVpCVflexr1D | H37: None | I37: Low Speed Steer | J37: ode23t | K37: 505 | L37: 3.199482 | M37: 74.209226 | N37: -0.33168045 | O37: =HYPERLINK(".\sm_car_250407_2318\sm_car_250407_2318_036_Ca115TrN_MaLSS_ode23t.png","figure") -> figure | P37: Pass | T37: =K37-'2022a_250206_1736'!K37 -> 0 | U37: =T37/'2022a_250206_1736'!K37 -> 0 | V37: =L37-'2022a_250206_1736'!L37 -> -0.2023742 | W37: =V37/'2022a_250206_1736'!L37 -> -0.059489346
A38: 37 | B38: 116 | C38: HambaLG | D38: 15DOF | E38: MFEval | F38: lintra | G38: f1Dr1D | H38: None | I38: WOT Braking | J38: ode23t | K38: 943 | L38: 4.2079208 | M38: 242.63119 | N38: 0.23279194 | O38: =HYPERLINK(".\sm_car_250407_2318\sm_car_250407_2318_037_Ca116TrN_MaWOT_ode23t.png","figure") -> figure | P38: Pass | T38: =K38-'2022a_250206_1736'!K38 -> 0 | U38: =T38/'2022a_250206_1736'!K38 -> 0 | V38: =L38-'2022a_250206_1736'!L38 -> -0.3593199 | W38: =V38/'2022a_250206_1736'!L38 -> -0.0786733
A39: 38 | B39: 116 | C39: HambaLG | D39: 15DOF | E39: MFEval | F39: lintra | G39: f1Dr1D | H39: None | I39: Low Speed Steer | J39: ode23t | K39: 1060 | L39: 4.6842099 | M39: 74.660234 | N39: -0.34043153 | O39: =HYPERLINK(".\sm_car_250407_2318\sm_car_250407_2318_038_Ca116TrN_MaLSS_ode23t.png","figure") -> figure | P39: Pass | T39: =K39-'2022a_250206_1736'!K39 -> 0 | U39: =T39/'2022a_250206_1736'!K39 -> 0 | V39: =L39-'2022a_250206_1736'!L39 -> -0.3611545 | W39: =V39/'2022a_250206_1736'!L39 -> -0.07158145
A40: 39 | B40: 117 | C40: HambaLG | D40: 15DOF | E40: MFEval | F40: lintra | G40: f1D3Dr1D | H40: None | I40: WOT Braking | J40: ode23t | K40: 951 | L40: 4.9274842 | M40: 241.56098 | N40: 0.2297138 | O40: =HYPERLINK(".\sm_car_250407_2318\sm_car_250407_2318_039_Ca117TrN_MaWOT_ode23t.png","figure") -> figure | P40: Pass | T40: =K40-'2022a_250206_1736'!K40 -> 0 | U40: =T40/'2022a_250206_1736'!K40 -> 0 | V40: =L40-'2022a_250206_1736'!L40 -> -0.2611465 | W40: =V40/'2022a_250206_1736'!L40 -> -0.050330524
...

Sheet 2022a_250414_0011
A1: Run | B1: Preset | C1: Body | D1: SuspF | E1: Tire | F1: TirDyn | G1: Drv | H1: Trail | I1: Mane | J1: Solv | K1: # Steps | L1: Time | M1: xFinal | N1: yFinal | O1: Figure | P1: Pass | R1: 14-Apr-2025 02:44:19
A2: 1 | B2: 0 | C2: HambaLG | D2: dwb | E2: MFEval | F2: steady | G2: f1Dr1D | H2: None | I2: WOT Braking | J2: ode23t | K2: 419 | L2: 7.7041647 | M2: 231.16978 | N2: -0.0042167209 | O2: =HYPERLINK(".\sm_car_250414_0011\sm_car_250414_0011_001_Ca000TrN_MaWOT_ode23t.png","figure") -> figure | P2: Pass | R2: MATHWORKS-OL1OH
A3: 2 | B3: 0 | C3: HambaLG | D3: dwb | E3: MFEval | F3: steady | G3: f1Dr1D | H3: None | I3: Low Speed Steer | J3: ode23t | K3: 535 | L3: 8.3454214 | M3: 71.237682 | N3: -0.53746461 | O3: =HYPERLINK(".\sm_car_250414_0011\sm_car_250414_0011_002_Ca000TrN_MaLSS_ode23t.png","figure") -> figure | P3: Pass | R3: 9.12.0.2529717 (R2022a) Update 8
A4: 3 | B4: 1 | C4: HambaLG | D4: dwb | E4: MFEval | F4: steady | G4: f1D3Dr1D | H4: None | I4: WOT Braking | J4: ode23t | K4: 422 | L4: 7.7448055 | M4: 230.37135 | N4: -0.010327302 | O4: =HYPERLINK(".\sm_car_250414_0011\sm_car_250414_0011_003_Ca001TrN_MaWOT_ode23t.png","figure") -> figure | P4: Pass | R4: MF-Swift Version: 2306
A5: 4 | B5: 1 | C5: HambaLG | D5: dwb | E5: MFEval | F5: steady | G5: f1D3Dr1D | H5: None | I5: Low Speed Steer | J5: ode23t | K5: 519 | L5: 8.6097983 | M5: 70.957359 | N5: -0.53535025 | O5: =HYPERLINK(".\sm_car_250414_0011\sm_car_250414_0011_004_Ca001TrN_MaLSS_ode23t.png","figure") -> figure | P5: Pass | R5: R22asrc v4p0 Excel Presets
A6: 5 | B6: 2 | C6: HambaLG | D6: dwb | E6: MFEval | F6: steady | G6: fCVpCVr1D | H6: None | I6: WOT Braking | J6: ode23t | K6: 450 | L6: 12.274566 | M6: 230.4117 | N6: 0.045171535 | O6: =HYPERLINK(".\sm_car_250414_0011\sm_car_250414_0011_005_Ca002TrN_MaWOT_ode23t.png","figure") -> figure | P6: Pass
A7: 6 | B7: 2 | C7: HambaLG | D7: dwb | E7: MFEval | F7: steady | G7: fCVpCVr1D | H7: None | I7: Low Speed Steer | J7: ode23t | K7: 539 | L7: 11.690374 | M7: 70.95575 | N7: -0.52983924 | O7: =HYPERLINK(".\sm_car_250414_0011\sm_car_250414_0011_006_Ca002TrN_MaLSS_ode23t.png","figure") -> figure | P7: Pass
A8: 7 | B8: 3 | C8: HambaLG | D8: dwb | E8: MFEval | F8: steady | G8: fCVpCVflexr1D | H8: None | I8: WOT Braking | J8: ode23t | K8: 492 | L8: 14.284985 | M8: 229.92983 | N8: 0.051963578 | O8: =HYPERLINK(".\sm_car_250414_0011\sm_car_250414_0011_007_Ca003TrN_MaWOT_ode23t.png","figure") -> figure | P8: Pass
A9: 8 | B9: 3 | C9: HambaLG | D9: dwb | E9: MFEval | F9: steady | G9: fCVpCVflexr1D | H9: None | I9: Low Speed Steer | J9: ode23t | K9: 563 | L9: 12.307639 | M9: 70.832837 | N9: -0.52854358 | O9: =HYPERLINK(".\sm_car_250414_0011\sm_car_250414_0011_008_Ca003TrN_MaLSS_ode23t.png","figure") -> figure | P9: Pass
A10: 9 | B10: 4 | C10: HambaLG | D10: dwb | E10: MFEval | F10: lintra | G10: f1Dr1D | H10: None | I10: WOT Braking | J10: ode23t | K10: 1083 | L10: 11.472076 | M10: 231.36499 | N10: -0.0056787031 | O10: =HYPERLINK(".\sm_car_250414_0011\sm_car_250414_0011_009_Ca004TrN_MaWOT_ode23t.png","figure") -> figure | P10: Pass
A11: 10 | B11: 4 | C11: HambaLG | D11: dwb | E11: MFEval | F11: lintra | G11: f1Dr1D | H11: None | I11: Low Speed Steer | J11: ode23t | K11: 1204 | L11: 13.481597 | M11: 71.25104 | N11: -0.5401557 | O11: =HYPERLINK(".\sm_car_250414_0011\sm_car_250414_0011_010_Ca004TrN_MaLSS_ode23t.png","figure") -> figure | P11: Pass
A12: 11 | B12: 5 | C12: HambaLG | D12: dwb | E12: MFEval | F12: lintra | G12: f1D3Dr1D | H12: None | I12: WOT Braking | J12: ode23t | K12: 1114 | L12: 13.334158 | M12: 230.37145 | N12: -0.01174034 | O12: =HYPERLINK(".\sm_car_250414_0011\sm_car_250414_0011_011_Ca005TrN_MaWOT_ode23t.png","figure") -> figure | P12: Pass
A13: 12 | B13: 5 | C13: HambaLG | D13: dwb | E13: MFEval | F13: lintra | G13: f1D3Dr1D | H13: None | I13: Low Speed Steer | J13: ode23t | K13: 1231 | L13: 14.740698 | M13: 70.973896 | N13: -0.53888735 | O13: =HYPERLINK(".\sm_car_250414_0011\sm_car_250414_0011_012_Ca005TrN_MaLSS_ode23t.png","figure") -> figure | P13: Pass
A14: 13 | B14: 6 | C14: HambaLG | D14: dwb | E14: MFEval | F14: lintra | G14: fCVpCVr1D | H14: None | I14: WOT Braking | J14: ode23t | K14: 1201 | L14: 16.677299 | M14: 230.37185 | N14: 0.048645333 | O14: =HYPERLINK(".\sm_car_250414_0011\sm_car_250414_0011_013_Ca006TrN_MaWOT_ode23t.png","figure") -> figure | P14: Pass
A15: 14 | B15: 6 | C15: HambaLG | D15: dwb | E15: MFEval | F15: lintra | G15: fCVpCVr1D | H15: None | I15: Low Speed Steer | J15: ode23t | K15: 1276 | L15: 16.049519 | M15: 70.95992 | N15: -0.53298054 | O15: =HYPERLINK(".\sm_car_250414_0011\sm_car_250414_0011_014_Ca006TrN_MaLSS_ode23t.png","figure") -> figure | P15: Pass
A16: 15 | B16: 7 | C16: HambaLG | D16: dwb | E16: MFEval | F16: lintra | G16: fCVpCVflexr1D | H16: None | I16: WOT Braking | J16: ode23t | K16: 1199 | L16: 21.206616 | M16: 229.86932 | N16: 0.054916401 | O16: =HYPERLINK(".\sm_car_250414_0011\sm_car_250414_0011_015_Ca007TrN_MaWOT_ode23t.png","figure") -> figure | P16: Pass
A17: 16 | B17: 7 | C17: HambaLG | D17: dwb | E17: MFEval | F17: lintra | G17: fCVpCVflexr1D | H17: None | I17: Low Speed Steer | J17: ode23t | K17: 1288 | L17: 19.105194 | M17: 70.831317 | N17: -0.53028788 | O17: =HYPERLINK(".\sm_car_250414_0011\sm_car_250414_0011_016_Ca007TrN_MaLSS_ode23t.png","figure") -> figure | P17: Pass
A18: 17 | B18: 16 | C18: HambaLG | D18: dwa | E18: MFEval | F18: steady | G18: f1Dr1D | H18: None | I18: WOT Braking | J18: ode23t | K18: 410 | L18: 5.8149413 | M18: 231.9547 | N18: -0.07180517 | O18: =HYPERLINK(".\sm_car_250414_0011\sm_car_250414_0011_017_Ca016TrN_MaWOT_ode23t.png","figure") -> figure | P18: Pass
A19: 18 | B19: 16 | C19: HambaLG | D19: dwa | E19: MFEval | F19: steady | G19: f1Dr1D | H19: None | I19: Low Speed Steer | J19: ode23t | K19: 487 | L19: 6.3880235 | M19: 71.519095 | N19: -0.021563941 | O19: =HYPERLINK(".\sm_car_250414_0011\sm_car_250414_0011_018_Ca016TrN_MaLSS_ode23t.png","figure") -> figure | P19: Pass
A20: 19 | B20: 32 | C20: HambaLG | D20: S2LAF | E20: MFEval | F20: steady | G20: f1Dr1D | H20: None | I20: WOT Braking | J20: ode23t | K20: 396 | L20: 7.2479873 | M20: 231.36824 | N20: 0.008704882 | O20: =HYPERLINK(".\sm_car_250414_0011\sm_car_250414_0011_019_Ca032TrN_MaWOT_ode23t.png","figure") -> figure | P20: Pass
A21: 20 | B21: 32 | C21: HambaLG | D21: S2LAF | E21: MFEval | F21: steady | G21: f1Dr1D | H21: None | I21: Low Speed Steer | J21: ode23t | K21: 519 | L21: 8.6368264 | M21: 71.259134 | N21: -0.52291335 | O21: =HYPERLINK(".\sm_car_250414_0011\sm_car_250414_0011_020_Ca032TrN_MaLSS_ode23t.png","figure") -> figure | P21: Pass
A22: 21 | B22: 48 | C22: HambaLG | D22: S2LAR | E22: MFEval | F22: steady | G22: f1Dr1D | H22: None | I22: WOT Braking | J22: ode23t | K22: 408 | L22: 7.6818017 | M22: 231.3545 | N22: -0.017846833 | O22: =HYPERLINK(".\sm_car_250414_0011\sm_car_250414_0011_021_Ca048TrN_MaWOT_ode23t.png","figure") -> figure | P22: Pass
A23: 22 | B23: 48 | C23: HambaLG | D23: S2LAR | E23: MFEval | F23: steady | G23: f1Dr1D | H23: None | I23: Low Speed Steer | J23: ode23t | K23: 523 | L23: 8.511845 | M23: 71.243091 | N23: -0.52846715 | O23: =HYPERLINK(".\sm_car_250414_0011\sm_car_250414_0011_022_Ca048TrN_MaLSS_ode23t.png","figure") -> figure | P23: Pass
A24: 23 | B24: 64 | C24: HambaLG | D24: 5S2LAF | E24: MFEval | F24: steady | G24: f1Dr1D | H24: None | I24: WOT Braking | J24: ode23t | K24: 401 | L24: 8.348922 | M24: 231.39133 | N24: 0.010575312 | O24: =HYPERLINK(".\sm_car_250414_0011\sm_car_250414_0011_023_Ca064TrN_MaWOT_ode23t.png","figure") -> figure | P24: Pass
A25: 24 | B25: 64 | C25: HambaLG | D25: 5S2LAF | E25: MFEval | F25: steady | G25: f1Dr1D | H25: None | I25: Low Speed Steer | J25: ode23t | K25: 515 | L25: 8.3129183 | M25: 71.257169 | N25: -0.51773374 | O25: =HYPERLINK(".\sm_car_250414_0011\sm_car_250414_0011_024_Ca064TrN_MaLSS_ode23t.png","figure") -> figure | P25: Pass
A26: 25 | B26: 80 | C26: HambaLG | D26: 5S2LAR | E26: MFEval | F26: steady | G26: f1Dr1D | H26: None | I26: WOT Braking | J26: ode23t | K26: 409 | L26: 9.6200009 | M26: 230.92214 | N26: -0.018904178 | O26: =HYPERLINK(".\sm_car_250414_0011\sm_car_250414_0011_025_Ca080TrN_MaWOT_ode23t.png","figure") -> figure | P26: Pass
A27: 26 | B27: 80 | C27: HambaLG | D27: 5S2LAR | E27: MFEval | F27: steady | G27: f1Dr1D | H27: None | I27: Low Speed Steer | J27: ode23t | K27: 511 | L27: 8.7490858 | M27: 71.241627 | N27: -0.5275313 | O27: =HYPERLINK(".\sm_car_250414_0011\sm_car_250414_0011_026_Ca080TrN_MaLSS_ode23t.png","figure") -> figure | P27: Pass
A28: 27 | B28: 96 | C28: HambaLG | D28: 5CS2LAF | E28: MFEval | F28: steady | G28: f1Dr1D | H28: None | I28: WOT Braking | J28: ode23t | K28: 408 | L28: 6.6635282 | M28: 233.14095 | N28: 0.022170176 | O28: =HYPERLINK(".\sm_car_250414_0011\sm_car_250414_0011_027_Ca096TrN_MaWOT_ode23t.png","figure") -> figure | P28: Pass
A29: 28 | B29: 96 | C29: HambaLG | D29: 5CS2LAF | E29: MFEval | F29: steady | G29: f1Dr1D | H29: None | I29: Low Speed Steer | J29: ode23t | K29: 508 | L29: 7.2024586 | M29: 71.764371 | N29: -0.52600636 | O29: =HYPERLINK(".\sm_car_250414_0011\sm_car_250414_0011_028_Ca096TrN_MaLSS_ode23t.png","figure") -> figure | P29: Pass
A30: 29 | B30: 112 | C30: HambaLG | D30: 15DOF | E30: MFEval | F30: steady | G30: f1Dr1D | H30: None | I30: WOT Braking | J30: ode23t | K30: 371 | L30: 2.5229352 | M30: 242.67152 | N30: 0.23455913 | O30: =HYPERLINK(".\sm_car_250414_0011\sm_car_250414_0011_029_Ca112TrN_MaWOT_ode23t.png","figure") -> figure | P30: Pass
A31: 30 | B31: 112 | C31: HambaLG | D31: 15DOF | E31: MFEval | F31: steady | G31: f1Dr1D | H31: None | I31: Low Speed Steer | J31: ode23t | K31: 480 | L31: 2.9196023 | M31: 74.659634 | N31: -0.33798931 | O31: =HYPERLINK(".\sm_car_250414_0011\sm_car_250414_0011_030_Ca112TrN_MaLSS_ode23t.png","figure") -> figure | P31: Pass
A32: 31 | B32: 113 | C32: HambaLG | D32: 15DOF | E32: MFEval | F32: steady | G32: f1D3Dr1D | H32: None | I32: WOT Braking | J32: ode23t | K32: 366 | L32: 3.0112947 | M32: 241.4988 | N32: 0.22933556 | O32: =HYPERLINK(".\sm_car_250414_0011\sm_car_250414_0011_031_Ca113TrN_MaWOT_ode23t.png","figure") -> figure | P32: Pass
A33: 32 | B33: 113 | C33: HambaLG | D33: 15DOF | E33: MFEval | F33: steady | G33: f1D3Dr1D | H33: None | I33: Low Speed Steer | J33: ode23t | K33: 487 | L33: 3.4082035 | M33: 74.346228 | N33: -0.33396938 | O33: =HYPERLINK(".\sm_car_250414_0011\sm_car_250414_0011_032_Ca113TrN_MaLSS_ode23t.png","figure") -> figure | P33: Pass
A34: 33 | B34: 114 | C34: HambaLG | D34: 15DOF | E34: MFEval | F34: steady | G34: fCVpCVr1D | H34: None | I34: WOT Braking | J34: ode23t | K34: 382 | L34: 3.2424673 | M34: 241.61378 | N34: 0.23021245 | O34: =HYPERLINK(".\sm_car_250414_0011\sm_car_250414_0011_033_Ca114TrN_MaWOT_ode23t.png","figure") -> figure | P34: Pass
A35: 34 | B35: 114 | C35: HambaLG | D35: 15DOF | E35: MFEval | F35: steady | G35: fCVpCVr1D | H35: None | I35: Low Speed Steer | J35: ode23t | K35: 482 | L35: 3.5859629 | M35: 74.351409 | N35: -0.3342006 | O35: =HYPERLINK(".\sm_car_250414_0011\sm_car_250414_0011_034_Ca114TrN_MaLSS_ode23t.png","figure") -> figure | P35: Pass
A36: 35 | B36: 115 | C36: HambaLG | D36: 15DOF | E36: MFEval | F36: steady | G36: fCVpCVflexr1D | H36: None | I36: WOT Braking | J36: ode23t | K36: 394 | L36: 3.2821257 | M36: 241.17294 | N36: 0.22843005 | O36: =HYPERLINK(".\sm_car_250414_0011\sm_car_250414_0011_035_Ca115TrN_MaWOT_ode23t.png","figure") -> figure | P36: Pass
A37: 36 | B37: 115 | C37: HambaLG | D37: 15DOF | E37: MFEval | F37: steady | G37: fCVpCVflexr1D | H37: None | I37: Low Speed Steer | J37: ode23t | K37: 505 | L37: 3.5367205 | M37: 74.209226 | N37: -0.33168045 | O37: =HYPERLINK(".\sm_car_250414_0011\sm_car_250414_0011_036_Ca115TrN_MaLSS_ode23t.png","figure") -> figure | P37: Pass
A38: 37 | B38: 116 | C38: HambaLG | D38: 15DOF | E38: MFEval | F38: lintra | G38: f1Dr1D | H38: None | I38: WOT Braking | J38: ode23t | K38: 943 | L38: 4.5694796 | M38: 242.63119 | N38: 0.23279194 | O38: =HYPERLINK(".\sm_car_250414_0011\sm_car_250414_0011_037_Ca116TrN_MaWOT_ode23t.png","figure") -> figure | P38: Pass
A39: 38 | B39: 116 | C39: HambaLG | D39: 15DOF | E39: MFEval | F39: lintra | G39: f1Dr1D | H39: None | I39: Low Speed Steer | J39: ode23t | K39: 1060 | L39: 5.2145184 | M39: 74.660234 | N39: -0.34043153 | O39: =HYPERLINK(".\sm_car_250414_0011\sm_car_250414_0011_038_Ca116TrN_MaLSS_ode23t.png","figure") -> figure | P39: Pass
A40: 39 | B40: 117 | C40: HambaLG | D40: 15DOF | E40: MFEval | F40: lintra | G40: f1D3Dr1D | H40: None | I40: WOT Braking | J40: ode23t | K40: 951 | L40: 5.2324727 | M40: 241.56098 | N40: 0.2297138 | O40: =HYPERLINK(".\sm_car_250414_0011\sm_car_250414_0011_039_Ca117TrN_MaWOT_ode23t.png","figure") -> figure | P40: Pass
...

Sheet 2022a_250418_1417
A1: Run | B1: Preset | C1: Body | D1: SuspF | E1: Tire | F1: TirDyn | G1: Drv | H1: Trail | I1: Mane | J1: Solv | K1: # Steps | L1: Time | M1: xFinal | N1: yFinal | O1: Figure | P1: Pass | R1: 18-Apr-2025 17:07:34
A2: 1 | B2: 0 | C2: HambaLG | D2: dwb | E2: MFEval | F2: steady | G2: f1Dr1D | H2: None | I2: WOT Braking | J2: ode23t | K2: 419 | L2: 6.336412 | M2: 231.16978 | N2: -0.0042167209 | O2: =HYPERLINK(".\sm_car_250418_1417\sm_car_250418_1417_001_Ca000TrN_MaWOT_ode23t.png","figure") -> figure | P2: Pass | R2: MATHWORKS-OL1OH
A3: 2 | B3: 0 | C3: HambaLG | D3: dwb | E3: MFEval | F3: steady | G3: f1Dr1D | H3: None | I3: Low Speed Steer | J3: ode23t | K3: 535 | L3: 7.5852963 | M3: 71.237682 | N3: -0.53746461 | O3: =HYPERLINK(".\sm_car_250418_1417\sm_car_250418_1417_002_Ca000TrN_MaLSS_ode23t.png","figure") -> figure | P3: Pass | R3: 9.12.0.2529717 (R2022a) Update 8
A4: 3 | B4: 1 | C4: HambaLG | D4: dwb | E4: MFEval | F4: steady | G4: f1D3Dr1D | H4: None | I4: WOT Braking | J4: ode23t | K4: 407 | L4: 6.8921933 | M4: 230.25741 | N4: -0.014633103 | O4: =HYPERLINK(".\sm_car_250418_1417\sm_car_250418_1417_003_Ca001TrN_MaWOT_ode23t.png","figure") -> figure | P4: Pass | R4: MF-Swift Version: 2306
A5: 4 | B5: 1 | C5: HambaLG | D5: dwb | E5: MFEval | F5: steady | G5: f1D3Dr1D | H5: None | I5: Low Speed Steer | J5: ode23t | K5: 519 | L5: 7.2882205 | M5: 70.957678 | N5: -0.53384777 | O5: =HYPERLINK(".\sm_car_250418_1417\sm_car_250418_1417_004_Ca001TrN_MaLSS_ode23t.png","figure") -> figure | P5: Pass | R5: R22asrc, 4p0 Add SWD, RST, SLA, FSH
A6: 5 | B6: 2 | C6: HambaLG | D6: dwb | E6: MFEval | F6: steady | G6: fCVpCVr1D | H6: None | I6: WOT Braking | J6: ode23t | K6: 438 | L6: 11.48862 | M6: 230.38665 | N6: 0.052552456 | O6: =HYPERLINK(".\sm_car_250418_1417\sm_car_250418_1417_005_Ca002TrN_MaWOT_ode23t.png","figure") -> figure | P6: Pass
A7: 6 | B7: 2 | C7: HambaLG | D7: dwb | E7: MFEval | F7: steady | G7: fCVpCVr1D | H7: None | I7: Low Speed Steer | J7: ode23t | K7: 531 | L7: 11.77198 | M7: 70.954822 | N7: -0.5320192 | O7: =HYPERLINK(".\sm_car_250418_1417\sm_car_250418_1417_006_Ca002TrN_MaLSS_ode23t.png","figure") -> figure | P7: Pass
A8: 7 | B8: 3 | C8: HambaLG | D8: dwb | E8: MFEval | F8: steady | G8: fCVpCVflexr1D | H8: None | I8: WOT Braking | J8: ode23t | K8: 462 | L8: 11.16296 | M8: 229.97511 | N8: 0.051365342 | O8: =HYPERLINK(".\sm_car_250418_1417\sm_car_250418_1417_007_Ca003TrN_MaWOT_ode23t.png","figure") -> figure | P8: Pass
A9: 8 | B9: 3 | C9: HambaLG | D9: dwb | E9: MFEval | F9: steady | G9: fCVpCVflexr1D | H9: None | I9: Low Speed Steer | J9: ode23t | K9: 583 | L9: 12.375929 | M9: 70.83711 | N9: -0.52818838 | O9: =HYPERLINK(".\sm_car_250418_1417\sm_car_250418_1417_008_Ca003TrN_MaLSS_ode23t.png","figure") -> figure | P9: Pass
A10: 9 | B10: 4 | C10: HambaLG | D10: dwb | E10: MFEval | F10: lintra | G10: f1Dr1D | H10: None | I10: WOT Braking | J10: ode23t | K10: 1083 | L10: 10.829682 | M10: 231.36499 | N10: -0.0056787031 | O10: =HYPERLINK(".\sm_car_250418_1417\sm_car_250418_1417_009_Ca004TrN_MaWOT_ode23t.png","figure") -> figure | P10: Pass
A11: 10 | B11: 4 | C11: HambaLG | D11: dwb | E11: MFEval | F11: lintra | G11: f1Dr1D | H11: None | I11: Low Speed Steer | J11: ode23t | K11: 1204 | L11: 12.818503 | M11: 71.25104 | N11: -0.5401557 | O11: =HYPERLINK(".\sm_car_250418_1417\sm_car_250418_1417_010_Ca004TrN_MaLSS_ode23t.png","figure") -> figure | P11: Pass
A12: 11 | B12: 5 | C12: HambaLG | D12: dwb | E12: MFEval | F12: lintra | G12: f1D3Dr1D | H12: None | I12: WOT Braking | J12: ode23t | K12: 1120 | L12: 12.695891 | M12: 230.33571 | N12: -0.0096169929 | O12: =HYPERLINK(".\sm_car_250418_1417\sm_car_250418_1417_011_Ca005TrN_MaWOT_ode23t.png","figure") -> figure | P12: Pass
A13: 12 | B13: 5 | C13: HambaLG | D13: dwb | E13: MFEval | F13: lintra | G13: f1D3Dr1D | H13: None | I13: Low Speed Steer | J13: ode23t | K13: 1231 | L13: 14.749834 | M13: 70.974774 | N13: -0.53847437 | O13: =HYPERLINK(".\sm_car_250418_1417\sm_car_250418_1417_012_Ca005TrN_MaLSS_ode23t.png","figure") -> figure | P13: Pass
A14: 13 | B14: 6 | C14: HambaLG | D14: dwb | E14: MFEval | F14: lintra | G14: fCVpCVr1D | H14: None | I14: WOT Braking | J14: ode23t | K14: 1205 | L14: 15.085846 | M14: 230.41604 | N14: 0.051014451 | O14: =HYPERLINK(".\sm_car_250418_1417\sm_car_250418_1417_013_Ca006TrN_MaWOT_ode23t.png","figure") -> figure | P14: Pass
A15: 14 | B15: 6 | C15: HambaLG | D15: dwb | E15: MFEval | F15: lintra | G15: fCVpCVr1D | H15: None | I15: Low Speed Steer | J15: ode23t | K15: 1302 | L15: 15.675547 | M15: 70.962447 | N15: -0.53379822 | O15: =HYPERLINK(".\sm_car_250418_1417\sm_car_250418_1417_014_Ca006TrN_MaLSS_ode23t.png","figure") -> figure | P15: Pass
A16: 15 | B16: 7 | C16: HambaLG | D16: dwb | E16: MFEval | F16: lintra | G16: fCVpCVflexr1D | H16: None | I16: WOT Braking | J16: ode23t | K16: 1187 | L16: 17.403167 | M16: 229.92141 | N16: 0.055510013 | O16: =HYPERLINK(".\sm_car_250418_1417\sm_car_250418_1417_015_Ca007TrN_MaWOT_ode23t.png","figure") -> figure | P16: Pass
A17: 16 | B17: 7 | C17: HambaLG | D17: dwb | E17: MFEval | F17: lintra | G17: fCVpCVflexr1D | H17: None | I17: Low Speed Steer | J17: ode23t | K17: 1264 | L17: 16.321782 | M17: 70.840156 | N17: -0.52950776 | O17: =HYPERLINK(".\sm_car_250418_1417\sm_car_250418_1417_016_Ca007TrN_MaLSS_ode23t.png","figure") -> figure | P17: Pass
A18: 17 | B18: 16 | C18: HambaLG | D18: dwa | E18: MFEval | F18: steady | G18: f1Dr1D | H18: None | I18: WOT Braking | J18: ode23t | K18: 410 | L18: 5.6343675 | M18: 231.9547 | N18: -0.07180517 | O18: =HYPERLINK(".\sm_car_250418_1417\sm_car_250418_1417_017_Ca016TrN_MaWOT_ode23t.png","figure") -> figure | P18: Pass
A19: 18 | B19: 16 | C19: HambaLG | D19: dwa | E19: MFEval | F19: steady | G19: f1Dr1D | H19: None | I19: Low Speed Steer | J19: ode23t | K19: 487 | L19: 5.9757213 | M19: 71.519095 | N19: -0.021563941 | O19: =HYPERLINK(".\sm_car_250418_1417\sm_car_250418_1417_018_Ca016TrN_MaLSS_ode23t.png","figure") -> figure | P19: Pass
A20: 19 | B20: 32 | C20: HambaLG | D20: S2LAF | E20: MFEval | F20: steady | G20: f1Dr1D | H20: None | I20: WOT Braking | J20: ode23t | K20: 396 | L20: 7.2425978 | M20: 231.36824 | N20: 0.008704882 | O20: =HYPERLINK(".\sm_car_250418_1417\sm_car_250418_1417_019_Ca032TrN_MaWOT_ode23t.png","figure") -> figure | P20: Pass
A21: 20 | B21: 32 | C21: HambaLG | D21: S2LAF | E21: MFEval | F21: steady | G21: f1Dr1D | H21: None | I21: Low Speed Steer | J21: ode23t | K21: 519 | L21: 8.9284359 | M21: 71.259134 | N21: -0.52291335 | O21: =HYPERLINK(".\sm_car_250418_1417\sm_car_250418_1417_020_Ca032TrN_MaLSS_ode23t.png","figure") -> figure | P21: Pass
A22: 21 | B22: 48 | C22: HambaLG | D22: S2LAR | E22: MFEval | F22: steady | G22: f1Dr1D | H22: None | I22: WOT Braking | J22: ode23t | K22: 408 | L22: 7.8997636 | M22: 231.3545 | N22: -0.017846833 | O22: =HYPERLINK(".\sm_car_250418_1417\sm_car_250418_1417_021_Ca048TrN_MaWOT_ode23t.png","figure") -> figure | P22: Pass
A23: 22 | B23: 48 | C23: HambaLG | D23: S2LAR | E23: MFEval | F23: steady | G23: f1Dr1D | H23: None | I23: Low Speed Steer | J23: ode23t | K23: 523 | L23: 8.5011024 | M23: 71.243091 | N23: -0.52846715 | O23: =HYPERLINK(".\sm_car_250418_1417\sm_car_250418_1417_022_Ca048TrN_MaLSS_ode23t.png","figure") -> figure | P23: Pass
A24: 23 | B24: 64 | C24: HambaLG | D24: 5S2LAF | E24: MFEval | F24: steady | G24: f1Dr1D | H24: None | I24: WOT Braking | J24: ode23t | K24: 401 | L24: 8.7375189 | M24: 231.39133 | N24: 0.010575312 | O24: =HYPERLINK(".\sm_car_250418_1417\sm_car_250418_1417_023_Ca064TrN_MaWOT_ode23t.png","figure") -> figure | P24: Pass
A25: 24 | B25: 64 | C25: HambaLG | D25: 5S2LAF | E25: MFEval | F25: steady | G25: f1Dr1D | H25: None | I25: Low Speed Steer | J25: ode23t | K25: 515 | L25: 8.3816886 | M25: 71.257169 | N25: -0.51773374 | O25: =HYPERLINK(".\sm_car_250418_1417\sm_car_250418_1417_024_Ca064TrN_MaLSS_ode23t.png","figure") -> figure | P25: Pass
A26: 25 | B26: 80 | C26: HambaLG | D26: 5S2LAR | E26: MFEval | F26: steady | G26: f1Dr1D | H26: None | I26: WOT Braking | J26: ode23t | K26: 409 | L26: 9.2979202 | M26: 230.92214 | N26: -0.018904178 | O26: =HYPERLINK(".\sm_car_250418_1417\sm_car_250418_1417_025_Ca080TrN_MaWOT_ode23t.png","figure") -> figure | P26: Pass
A27: 26 | B27: 80 | C27: HambaLG | D27: 5S2LAR | E27: MFEval | F27: steady | G27: f1Dr1D | H27: None | I27: Low Speed Steer | J27: ode23t | K27: 511 | L27: 8.6093963 | M27: 71.241627 | N27: -0.5275313 | O27: =HYPERLINK(".\sm_car_250418_1417\sm_car_250418_1417_026_Ca080TrN_MaLSS_ode23t.png","figure") -> figure | P27: Pass
A28: 27 | B28: 96 | C28: HambaLG | D28: 5CS2LAF | E28: MFEval | F28: steady | G28: f1Dr1D | H28: None | I28: WOT Braking | J28: ode23t | K28: 408 | L28: 6.6053064 | M28: 233.14095 | N28: 0.022170176 | O28: =HYPERLINK(".\sm_car_250418_1417\sm_car_250418_1417_027_Ca096TrN_MaWOT_ode23t.png","figure") -> figure | P28: Pass
A29: 28 | B29: 96 | C29: HambaLG | D29: 5CS2LAF | E29: MFEval | F29: steady | G29: f1Dr1D | H29: None | I29: Low Speed Steer | J29: ode23t | K29: 508 | L29: 7.0457044 | M29: 71.764371 | N29: -0.52600636 | O29: =HYPERLINK(".\sm_car_250418_1417\sm_car_250418_1417_028_Ca096TrN_MaLSS_ode23t.png","figure") -> figure | P29: Pass
A30: 29 | B30: 112 | C30: HambaLG | D30: 15DOF | E30: MFEval | F30: steady | G30: f1Dr1D | H30: None | I30: WOT Braking | J30: ode23t | K30: 371 | L30: 2.4681811 | M30: 242.67152 | N30: 0.23455913 | O30: =HYPERLINK(".\sm_car_250418_1417\sm_car_250418_1417_029_Ca112TrN_MaWOT_ode23t.png","figure") -> figure | P30: Pass
A31: 30 | B31: 112 | C31: HambaLG | D31: 15DOF | E31: MFEval | F31: steady | G31: f1Dr1D | H31: None | I31: Low Speed Steer | J31: ode23t | K31: 480 | L31: 2.7471233 | M31: 74.659634 | N31: -0.33798931 | O31: =HYPERLINK(".\sm_car_250418_1417\sm_car_250418_1417_030_Ca112TrN_MaLSS_ode23t.png","figure") -> figure | P31: Pass
A32: 31 | B32: 113 | C32: HambaLG | D32: 15DOF | E32: MFEval | F32: steady | G32: f1D3Dr1D | H32: None | I32: WOT Braking | J32: ode23t | K32: 365 | L32: 3.160326 | M32: 241.58096 | N32: 0.23108069 | O32: =HYPERLINK(".\sm_car_250418_1417\sm_car_250418_1417_031_Ca113TrN_MaWOT_ode23t.png","figure") -> figure | P32: Pass
A33: 32 | B33: 113 | C33: HambaLG | D33: 15DOF | E33: MFEval | F33: steady | G33: f1D3Dr1D | H33: None | I33: Low Speed Steer | J33: ode23t | K33: 472 | L33: 2.7871249 | M33: 74.347328 | N33: -0.33499339 | O33: =HYPERLINK(".\sm_car_250418_1417\sm_car_250418_1417_032_Ca113TrN_MaLSS_ode23t.png","figure") -> figure | P33: Pass
A34: 33 | B34: 114 | C34: HambaLG | D34: 15DOF | E34: MFEval | F34: steady | G34: fCVpCVr1D | H34: None | I34: WOT Braking | J34: ode23t | K34: 373 | L34: 3.0219925 | M34: 241.4723 | N34: 0.22924441 | O34: =HYPERLINK(".\sm_car_250418_1417\sm_car_250418_1417_033_Ca114TrN_MaWOT_ode23t.png","figure") -> figure | P34: Pass
A35: 34 | B35: 114 | C35: HambaLG | D35: 15DOF | E35: MFEval | F35: steady | G35: fCVpCVr1D | H35: None | I35: Low Speed Steer | J35: ode23t | K35: 480 | L35: 3.0916611 | M35: 74.350536 | N35: -0.33405185 | O35: =HYPERLINK(".\sm_car_250418_1417\sm_car_250418_1417_034_Ca114TrN_MaLSS_ode23t.png","figure") -> figure | P35: Pass
A36: 35 | B36: 115 | C36: HambaLG | D36: 15DOF | E36: MFEval | F36: steady | G36: fCVpCVflexr1D | H36: None | I36: WOT Braking | J36: ode23t | K36: 389 | L36: 3.1475967 | M36: 241.20739 | N36: 0.22780539 | O36: =HYPERLINK(".\sm_car_250418_1417\sm_car_250418_1417_035_Ca115TrN_MaWOT_ode23t.png","figure") -> figure | P36: Pass
A37: 36 | B37: 115 | C37: HambaLG | D37: 15DOF | E37: MFEval | F37: steady | G37: fCVpCVflexr1D | H37: None | I37: Low Speed Steer | J37: ode23t | K37: 523 | L37: 3.7052205 | M37: 74.209863 | N37: -0.33245455 | O37: =HYPERLINK(".\sm_car_250418_1417\sm_car_250418_1417_036_Ca115TrN_MaLSS_ode23t.png","figure") -> figure | P37: Pass
A38: 37 | B38: 116 | C38: HambaLG | D38: 15DOF | E38: MFEval | F38: lintra | G38: f1Dr1D | H38: None | I38: WOT Braking | J38: ode23t | K38: 943 | L38: 4.4116395 | M38: 242.63119 | N38: 0.23279194 | O38: =HYPERLINK(".\sm_car_250418_1417\sm_car_250418_1417_037_Ca116TrN_MaWOT_ode23t.png","figure") -> figure | P38: Pass
A39: 38 | B39: 116 | C39: HambaLG | D39: 15DOF | E39: MFEval | F39: lintra | G39: f1Dr1D | H39: None | I39: Low Speed Steer | J39: ode23t | K39: 1060 | L39: 4.7064446 | M39: 74.660234 | N39: -0.34043153 | O39: =HYPERLINK(".\sm_car_250418_1417\sm_car_250418_1417_038_Ca116TrN_MaLSS_ode23t.png","figure") -> figure | P39: Pass
A40: 39 | B40: 117 | C40: HambaLG | D40: 15DOF | E40: MFEval | F40: lintra | G40: f1D3Dr1D | H40: None | I40: WOT Braking | J40: ode23t | K40: 955 | L40: 4.9141595 | M40: 241.25997 | N40: 0.23003619 | O40: =HYPERLINK(".\sm_car_250418_1417\sm_car_250418_1417_039_Ca117TrN_MaWOT_ode23t.png","figure") -> figure | P40: Pass
...

Sheet 2022a_250503_1632
A1: Run | B1: Preset | C1: Body | D1: SuspF | E1: Tire | F1: TirDyn | G1: Drv | H1: Trail | I1: Mane | J1: Solv | K1: # Steps | L1: Time | M1: xFinal | N1: yFinal | O1: Figure | P1: Pass | R1: 03-May-2025 19:15:08
A2: 1 | B2: 0 | C2: HambaLG | D2: dwb | E2: MFEval | F2: steady | G2: f1Dr1D | H2: None | I2: WOT Braking | J2: ode23t | K2: 429 | L2: 7.5553789 | M2: 231.11452 | N2: -0.0051214569 | O2: =HYPERLINK(".\sm_car_250503_1632\sm_car_250503_1632_001_Ca000TrN_MaWOT_ode23t.png","figure") -> figure | P2: Pass | R2: MATHWORKS-OL1OH
A3: 2 | B3: 0 | C3: HambaLG | D3: dwb | E3: MFEval | F3: steady | G3: f1Dr1D | H3: None | I3: Low Speed Steer | J3: ode23t | K3: 525 | L3: 7.8671312 | M3: 71.235932 | N3: -0.53998686 | O3: =HYPERLINK(".\sm_car_250503_1632\sm_car_250503_1632_002_Ca000TrN_MaLSS_ode23t.png","figure") -> figure | P3: Pass | R3: 9.12.0.2529717 (R2022a) Update 8
A4: 3 | B4: 1 | C4: HambaLG | D4: dwb | E4: MFEval | F4: steady | G4: f1D3Dr1D | H4: None | I4: WOT Braking | J4: ode23t | K4: 408 | L4: 10.580148 | M4: 230.12646 | N4: -0.016493096 | O4: =HYPERLINK(".\sm_car_250503_1632\sm_car_250503_1632_003_Ca001TrN_MaWOT_ode23t.png","figure") -> figure | P4: Pass | R4: MF-Swift Version: 2306
